2023-08-19 21:31:29,224 INFO: Potterylog startup [in /Users/dorritochan/Documents/IT dojo/POTTERY/potterylog/app/__init__.py:41]
2023-08-19 21:31:40,423 ERROR: Exception on /addpot [POST] [in /Users/dorritochan/Documents/IT dojo/POTTERY/potterylog/venv/lib/python3.9/site-packages/flask/app.py:1741]
Traceback (most recent call last):
  File "/Users/dorritochan/Documents/IT dojo/POTTERY/potterylog/venv/lib/python3.9/site-packages/flask/app.py", line 2525, in wsgi_app
    response = self.full_dispatch_request()
  File "/Users/dorritochan/Documents/IT dojo/POTTERY/potterylog/venv/lib/python3.9/site-packages/flask/app.py", line 1822, in full_dispatch_request
    rv = self.handle_user_exception(e)
  File "/Users/dorritochan/Documents/IT dojo/POTTERY/potterylog/venv/lib/python3.9/site-packages/flask/app.py", line 1820, in full_dispatch_request
    rv = self.dispatch_request()
  File "/Users/dorritochan/Documents/IT dojo/POTTERY/potterylog/venv/lib/python3.9/site-packages/flask/app.py", line 1796, in dispatch_request
    return self.ensure_sync(self.view_functions[rule.endpoint])(**view_args)
  File "/Users/dorritochan/Documents/IT dojo/POTTERY/potterylog/venv/lib/python3.9/site-packages/flask_login/utils.py", line 290, in decorated_view
    return current_app.ensure_sync(func)(*args, **kwargs)
  File "/Users/dorritochan/Documents/IT dojo/POTTERY/potterylog/app/controller.py", line 109, in add_pot
    if request.method == 'POST' and current_user.is_authenticated and form.validate_on_submit():
  File "/Users/dorritochan/Documents/IT dojo/POTTERY/potterylog/venv/lib/python3.9/site-packages/flask_wtf/form.py", line 86, in validate_on_submit
    return self.is_submitted() and self.validate(extra_validators=extra_validators)
  File "/Users/dorritochan/Documents/IT dojo/POTTERY/potterylog/venv/lib/python3.9/site-packages/wtforms/form.py", line 329, in validate
    return super().validate(extra)
  File "/Users/dorritochan/Documents/IT dojo/POTTERY/potterylog/venv/lib/python3.9/site-packages/wtforms/form.py", line 146, in validate
    if not field.validate(self, extra):
  File "/Users/dorritochan/Documents/IT dojo/POTTERY/potterylog/venv/lib/python3.9/site-packages/wtforms/fields/list.py", line 132, in validate
    self._run_validation_chain(form, chain)
  File "/Users/dorritochan/Documents/IT dojo/POTTERY/potterylog/venv/lib/python3.9/site-packages/wtforms/fields/core.py", line 262, in _run_validation_chain
    validator(form, self)
  File "/Users/dorritochan/Documents/IT dojo/POTTERY/potterylog/app/forms.py", line 90, in validate_used_glazes
    if Glaze.query.get(glaze.data) is None:
  File "<string>", line 2, in get
  File "/Users/dorritochan/Documents/IT dojo/POTTERY/potterylog/venv/lib/python3.9/site-packages/sqlalchemy/util/deprecations.py", line 383, in warned
    return fn(*args, **kwargs)  # type: ignore[no-any-return]
  File "/Users/dorritochan/Documents/IT dojo/POTTERY/potterylog/venv/lib/python3.9/site-packages/sqlalchemy/orm/query.py", line 1130, in get
    return self._get_impl(ident, loading.load_on_pk_identity)
  File "/Users/dorritochan/Documents/IT dojo/POTTERY/potterylog/venv/lib/python3.9/site-packages/sqlalchemy/orm/query.py", line 1139, in _get_impl
    return self.session._get_impl(
  File "/Users/dorritochan/Documents/IT dojo/POTTERY/potterylog/venv/lib/python3.9/site-packages/sqlalchemy/orm/session.py", line 3589, in _get_impl
    raise sa_exc.InvalidRequestError(
sqlalchemy.exc.InvalidRequestError: Incorrect number of values in identifier to formulate primary key for session.get(); primary key columns are 'glaze.id'
2023-08-19 21:33:28,834 INFO: Potterylog startup [in /Users/dorritochan/Documents/IT dojo/POTTERY/potterylog/app/__init__.py:41]
2023-08-19 21:33:35,979 ERROR: Exception on /addpot [POST] [in /Users/dorritochan/Documents/IT dojo/POTTERY/potterylog/venv/lib/python3.9/site-packages/flask/app.py:1741]
Traceback (most recent call last):
  File "/Users/dorritochan/Documents/IT dojo/POTTERY/potterylog/venv/lib/python3.9/site-packages/flask/app.py", line 2525, in wsgi_app
    response = self.full_dispatch_request()
  File "/Users/dorritochan/Documents/IT dojo/POTTERY/potterylog/venv/lib/python3.9/site-packages/flask/app.py", line 1822, in full_dispatch_request
    rv = self.handle_user_exception(e)
  File "/Users/dorritochan/Documents/IT dojo/POTTERY/potterylog/venv/lib/python3.9/site-packages/flask/app.py", line 1820, in full_dispatch_request
    rv = self.dispatch_request()
  File "/Users/dorritochan/Documents/IT dojo/POTTERY/potterylog/venv/lib/python3.9/site-packages/flask/app.py", line 1796, in dispatch_request
    return self.ensure_sync(self.view_functions[rule.endpoint])(**view_args)
  File "/Users/dorritochan/Documents/IT dojo/POTTERY/potterylog/venv/lib/python3.9/site-packages/flask_login/utils.py", line 290, in decorated_view
    return current_app.ensure_sync(func)(*args, **kwargs)
  File "/Users/dorritochan/Documents/IT dojo/POTTERY/potterylog/app/controller.py", line 109, in add_pot
    if request.method == 'POST' and current_user.is_authenticated and form.validate_on_submit():
  File "/Users/dorritochan/Documents/IT dojo/POTTERY/potterylog/venv/lib/python3.9/site-packages/flask_wtf/form.py", line 86, in validate_on_submit
    return self.is_submitted() and self.validate(extra_validators=extra_validators)
  File "/Users/dorritochan/Documents/IT dojo/POTTERY/potterylog/venv/lib/python3.9/site-packages/wtforms/form.py", line 329, in validate
    return super().validate(extra)
  File "/Users/dorritochan/Documents/IT dojo/POTTERY/potterylog/venv/lib/python3.9/site-packages/wtforms/form.py", line 146, in validate
    if not field.validate(self, extra):
  File "/Users/dorritochan/Documents/IT dojo/POTTERY/potterylog/venv/lib/python3.9/site-packages/wtforms/fields/list.py", line 132, in validate
    self._run_validation_chain(form, chain)
  File "/Users/dorritochan/Documents/IT dojo/POTTERY/potterylog/venv/lib/python3.9/site-packages/wtforms/fields/core.py", line 262, in _run_validation_chain
    validator(form, self)
  File "/Users/dorritochan/Documents/IT dojo/POTTERY/potterylog/app/forms.py", line 90, in validate_used_glazes
    if Glaze.query.get(glaze.data) is None:
  File "<string>", line 2, in get
  File "/Users/dorritochan/Documents/IT dojo/POTTERY/potterylog/venv/lib/python3.9/site-packages/sqlalchemy/util/deprecations.py", line 383, in warned
    return fn(*args, **kwargs)  # type: ignore[no-any-return]
  File "/Users/dorritochan/Documents/IT dojo/POTTERY/potterylog/venv/lib/python3.9/site-packages/sqlalchemy/orm/query.py", line 1130, in get
    return self._get_impl(ident, loading.load_on_pk_identity)
  File "/Users/dorritochan/Documents/IT dojo/POTTERY/potterylog/venv/lib/python3.9/site-packages/sqlalchemy/orm/query.py", line 1139, in _get_impl
    return self.session._get_impl(
  File "/Users/dorritochan/Documents/IT dojo/POTTERY/potterylog/venv/lib/python3.9/site-packages/sqlalchemy/orm/session.py", line 3589, in _get_impl
    raise sa_exc.InvalidRequestError(
sqlalchemy.exc.InvalidRequestError: Incorrect number of values in identifier to formulate primary key for session.get(); primary key columns are 'glaze.id'
2023-08-19 22:07:08,982 INFO: Potterylog startup [in /Users/dorritochan/Documents/IT dojo/POTTERY/potterylog/app/__init__.py:41]
