2023-09-06 20:21:28,345 ERROR: Exception on /editpot/58 [GET] [in /Users/dorritochan/Documents/IT dojo/POTTERY/potterylog/venv/lib/python3.9/site-packages/flask/app.py:1741]
Traceback (most recent call last):
  File "/Users/dorritochan/Documents/IT dojo/POTTERY/potterylog/venv/lib/python3.9/site-packages/flask/app.py", line 2525, in wsgi_app
    response = self.full_dispatch_request()
  File "/Users/dorritochan/Documents/IT dojo/POTTERY/potterylog/venv/lib/python3.9/site-packages/flask/app.py", line 1822, in full_dispatch_request
    rv = self.handle_user_exception(e)
  File "/Users/dorritochan/Documents/IT dojo/POTTERY/potterylog/venv/lib/python3.9/site-packages/flask/app.py", line 1820, in full_dispatch_request
    rv = self.dispatch_request()
  File "/Users/dorritochan/Documents/IT dojo/POTTERY/potterylog/venv/lib/python3.9/site-packages/flask/app.py", line 1796, in dispatch_request
    return self.ensure_sync(self.view_functions[rule.endpoint])(**view_args)
  File "/Users/dorritochan/Documents/IT dojo/POTTERY/potterylog/venv/lib/python3.9/site-packages/flask_login/utils.py", line 290, in decorated_view
    return current_app.ensure_sync(func)(*args, **kwargs)
  File "/Users/dorritochan/Documents/IT dojo/POTTERY/potterylog/app/controller.py", line 334, in edit_pot
    populate_select_field_data(form, pot)
  File "/Users/dorritochan/Documents/IT dojo/POTTERY/potterylog/app/utils.py", line 62, in populate_select_field_data
    print(form.form_field)
AttributeError: 'AddPotForm' object has no attribute 'form_field'
2023-09-06 20:22:50,635 INFO: Potterylog startup [in /Users/dorritochan/Documents/IT dojo/POTTERY/potterylog/app/__init__.py:41]
2023-09-06 20:24:39,151 INFO: Potterylog startup [in /Users/dorritochan/Documents/IT dojo/POTTERY/potterylog/app/__init__.py:41]
2023-09-06 20:33:34,852 INFO: Potterylog startup [in /Users/dorritochan/Documents/IT dojo/POTTERY/potterylog/app/__init__.py:41]
2023-09-06 20:38:18,566 INFO: Potterylog startup [in /Users/dorritochan/Documents/IT dojo/POTTERY/potterylog/app/__init__.py:41]
2023-09-06 20:39:23,067 INFO: Potterylog startup [in /Users/dorritochan/Documents/IT dojo/POTTERY/potterylog/app/__init__.py:41]
2023-09-06 20:39:39,718 INFO: Potterylog startup [in /Users/dorritochan/Documents/IT dojo/POTTERY/potterylog/app/__init__.py:41]
2023-09-06 20:42:02,571 INFO: Potterylog startup [in /Users/dorritochan/Documents/IT dojo/POTTERY/potterylog/app/__init__.py:41]
2023-09-06 20:43:02,910 INFO: Potterylog startup [in /Users/dorritochan/Documents/IT dojo/POTTERY/potterylog/app/__init__.py:41]
2023-09-06 20:46:51,058 INFO: Potterylog startup [in /Users/dorritochan/Documents/IT dojo/POTTERY/potterylog/app/__init__.py:41]
2023-09-06 20:49:45,673 INFO: Potterylog startup [in /Users/dorritochan/Documents/IT dojo/POTTERY/potterylog/app/__init__.py:41]
2023-09-06 20:58:25,734 INFO: Potterylog startup [in /Users/dorritochan/Documents/IT dojo/POTTERY/potterylog/app/__init__.py:41]
2023-09-06 20:58:28,223 ERROR: Exception on /editpot/58 [GET] [in /Users/dorritochan/Documents/IT dojo/POTTERY/potterylog/venv/lib/python3.9/site-packages/flask/app.py:1741]
Traceback (most recent call last):
  File "/Users/dorritochan/Documents/IT dojo/POTTERY/potterylog/venv/lib/python3.9/site-packages/flask/app.py", line 2525, in wsgi_app
    response = self.full_dispatch_request()
  File "/Users/dorritochan/Documents/IT dojo/POTTERY/potterylog/venv/lib/python3.9/site-packages/flask/app.py", line 1822, in full_dispatch_request
    rv = self.handle_user_exception(e)
  File "/Users/dorritochan/Documents/IT dojo/POTTERY/potterylog/venv/lib/python3.9/site-packages/flask/app.py", line 1820, in full_dispatch_request
    rv = self.dispatch_request()
  File "/Users/dorritochan/Documents/IT dojo/POTTERY/potterylog/venv/lib/python3.9/site-packages/flask/app.py", line 1796, in dispatch_request
    return self.ensure_sync(self.view_functions[rule.endpoint])(**view_args)
  File "/Users/dorritochan/Documents/IT dojo/POTTERY/potterylog/venv/lib/python3.9/site-packages/flask_login/utils.py", line 290, in decorated_view
    return current_app.ensure_sync(func)(*args, **kwargs)
  File "/Users/dorritochan/Documents/IT dojo/POTTERY/potterylog/app/controller.py", line 334, in edit_pot
    populate_select_field_data(form, pot)
  File "/Users/dorritochan/Documents/IT dojo/POTTERY/potterylog/app/utils.py", line 61, in populate_select_field_data
    setattr(form, form_field + ".data", get_field_id_or_default(pot_field))
  File "/Users/dorritochan/Documents/IT dojo/POTTERY/potterylog/app/utils.py", line 47, in get_field_id_or_default
    return pot_select_field.id if pot_select_field else 0
AttributeError: 'int' object has no attribute 'id'
2023-09-06 20:58:42,024 INFO: Potterylog startup [in /Users/dorritochan/Documents/IT dojo/POTTERY/potterylog/app/__init__.py:41]
2023-09-06 20:59:17,986 INFO: Potterylog startup [in /Users/dorritochan/Documents/IT dojo/POTTERY/potterylog/app/__init__.py:41]
