2023-09-06 20:59:19,705 ERROR: Exception on /editpot/58 [GET] [in /Users/dorritochan/Documents/IT dojo/POTTERY/potterylog/venv/lib/python3.9/site-packages/flask/app.py:1741]
Traceback (most recent call last):
  File "/Users/dorritochan/Documents/IT dojo/POTTERY/potterylog/venv/lib/python3.9/site-packages/sqlalchemy/orm/mapper.py", line 2491, in get_property
    return self._props[key]
KeyError: 'made_with_clay'

The above exception was the direct cause of the following exception:

Traceback (most recent call last):
  File "/Users/dorritochan/Documents/IT dojo/POTTERY/potterylog/venv/lib/python3.9/site-packages/flask/app.py", line 2525, in wsgi_app
    response = self.full_dispatch_request()
  File "/Users/dorritochan/Documents/IT dojo/POTTERY/potterylog/venv/lib/python3.9/site-packages/flask/app.py", line 1822, in full_dispatch_request
    rv = self.handle_user_exception(e)
  File "/Users/dorritochan/Documents/IT dojo/POTTERY/potterylog/venv/lib/python3.9/site-packages/flask/app.py", line 1820, in full_dispatch_request
    rv = self.dispatch_request()
  File "/Users/dorritochan/Documents/IT dojo/POTTERY/potterylog/venv/lib/python3.9/site-packages/flask/app.py", line 1796, in dispatch_request
    return self.ensure_sync(self.view_functions[rule.endpoint])(**view_args)
  File "/Users/dorritochan/Documents/IT dojo/POTTERY/potterylog/venv/lib/python3.9/site-packages/flask_login/utils.py", line 284, in decorated_view
    elif not current_user.is_authenticated:
  File "/Users/dorritochan/Documents/IT dojo/POTTERY/potterylog/venv/lib/python3.9/site-packages/werkzeug/local.py", line 316, in __get__
    obj = instance._get_current_object()  # type: ignore[misc]
  File "/Users/dorritochan/Documents/IT dojo/POTTERY/potterylog/venv/lib/python3.9/site-packages/werkzeug/local.py", line 520, in _get_current_object
    return get_name(local())  # type: ignore
  File "/Users/dorritochan/Documents/IT dojo/POTTERY/potterylog/venv/lib/python3.9/site-packages/flask_login/utils.py", line 25, in <lambda>
    current_user = LocalProxy(lambda: _get_user())
  File "/Users/dorritochan/Documents/IT dojo/POTTERY/potterylog/venv/lib/python3.9/site-packages/flask_login/utils.py", line 372, in _get_user
    current_app.login_manager._load_user()
  File "/Users/dorritochan/Documents/IT dojo/POTTERY/potterylog/venv/lib/python3.9/site-packages/flask_login/login_manager.py", line 364, in _load_user
    user = self._user_callback(user_id)
  File "/Users/dorritochan/Documents/IT dojo/POTTERY/potterylog/app/models.py", line 31, in load_user
    return User.query.get(int(id))
  File "/Users/dorritochan/Documents/IT dojo/POTTERY/potterylog/venv/lib/python3.9/site-packages/flask_sqlalchemy/model.py", line 30, in __get__
    return cls.query_class(
  File "/Users/dorritochan/Documents/IT dojo/POTTERY/potterylog/venv/lib/python3.9/site-packages/sqlalchemy/orm/query.py", line 273, in __init__
    self._set_entities(entities)
  File "/Users/dorritochan/Documents/IT dojo/POTTERY/potterylog/venv/lib/python3.9/site-packages/sqlalchemy/orm/query.py", line 282, in _set_entities
    self._raw_columns = [
  File "/Users/dorritochan/Documents/IT dojo/POTTERY/potterylog/venv/lib/python3.9/site-packages/sqlalchemy/orm/query.py", line 283, in <listcomp>
    coercions.expect(
  File "/Users/dorritochan/Documents/IT dojo/POTTERY/potterylog/venv/lib/python3.9/site-packages/sqlalchemy/sql/coercions.py", line 406, in expect
    insp._post_inspect
  File "/Users/dorritochan/Documents/IT dojo/POTTERY/potterylog/venv/lib/python3.9/site-packages/sqlalchemy/util/langhelpers.py", line 1254, in __get__
    obj.__dict__[self.__name__] = result = self.fget(obj)
  File "/Users/dorritochan/Documents/IT dojo/POTTERY/potterylog/venv/lib/python3.9/site-packages/sqlalchemy/orm/mapper.py", line 2693, in _post_inspect
    self._check_configure()
  File "/Users/dorritochan/Documents/IT dojo/POTTERY/potterylog/venv/lib/python3.9/site-packages/sqlalchemy/orm/mapper.py", line 2374, in _check_configure
    _configure_registries({self.registry}, cascade=True)
  File "/Users/dorritochan/Documents/IT dojo/POTTERY/potterylog/venv/lib/python3.9/site-packages/sqlalchemy/orm/mapper.py", line 4116, in _configure_registries
    _do_configure_registries(registries, cascade)
  File "/Users/dorritochan/Documents/IT dojo/POTTERY/potterylog/venv/lib/python3.9/site-packages/sqlalchemy/orm/mapper.py", line 4158, in _do_configure_registries
    mapper._post_configure_properties()
  File "/Users/dorritochan/Documents/IT dojo/POTTERY/potterylog/venv/lib/python3.9/site-packages/sqlalchemy/orm/mapper.py", line 2391, in _post_configure_properties
    prop.init()
  File "/Users/dorritochan/Documents/IT dojo/POTTERY/potterylog/venv/lib/python3.9/site-packages/sqlalchemy/orm/interfaces.py", line 544, in init
    self.do_init()
  File "/Users/dorritochan/Documents/IT dojo/POTTERY/potterylog/venv/lib/python3.9/site-packages/sqlalchemy/orm/relationships.py", line 1637, in do_init
    self._generate_backref()
  File "/Users/dorritochan/Documents/IT dojo/POTTERY/potterylog/venv/lib/python3.9/site-packages/sqlalchemy/orm/relationships.py", line 2128, in _generate_backref
    self._add_reverse_property(self.back_populates)
  File "/Users/dorritochan/Documents/IT dojo/POTTERY/potterylog/venv/lib/python3.9/site-packages/sqlalchemy/orm/relationships.py", line 1569, in _add_reverse_property
    other = self.mapper.get_property(key, _configure_mappers=False)
  File "/Users/dorritochan/Documents/IT dojo/POTTERY/potterylog/venv/lib/python3.9/site-packages/sqlalchemy/orm/mapper.py", line 2493, in get_property
    raise sa_exc.InvalidRequestError(
sqlalchemy.exc.InvalidRequestError: Mapper 'Mapper[Pot(pot)]' has no property 'made_with_clay'.  If this property was indicated from other mappers or configure events, ensure registry.configure() has been called.
2023-09-06 20:59:32,523 INFO: Potterylog startup [in /Users/dorritochan/Documents/IT dojo/POTTERY/potterylog/app/__init__.py:41]
2023-09-06 21:04:02,207 INFO: Potterylog startup [in /Users/dorritochan/Documents/IT dojo/POTTERY/potterylog/app/__init__.py:41]
2023-09-06 21:17:46,227 INFO: Potterylog startup [in /Users/dorritochan/Documents/IT dojo/POTTERY/potterylog/app/__init__.py:41]
2023-09-06 21:17:48,685 ERROR: Exception on /editpot/58 [GET] [in /Users/dorritochan/Documents/IT dojo/POTTERY/potterylog/venv/lib/python3.9/site-packages/flask/app.py:1741]
Traceback (most recent call last):
  File "/Users/dorritochan/Documents/IT dojo/POTTERY/potterylog/venv/lib/python3.9/site-packages/flask/app.py", line 2525, in wsgi_app
    response = self.full_dispatch_request()
  File "/Users/dorritochan/Documents/IT dojo/POTTERY/potterylog/venv/lib/python3.9/site-packages/flask/app.py", line 1822, in full_dispatch_request
    rv = self.handle_user_exception(e)
  File "/Users/dorritochan/Documents/IT dojo/POTTERY/potterylog/venv/lib/python3.9/site-packages/flask/app.py", line 1820, in full_dispatch_request
    rv = self.dispatch_request()
  File "/Users/dorritochan/Documents/IT dojo/POTTERY/potterylog/venv/lib/python3.9/site-packages/flask/app.py", line 1796, in dispatch_request
    return self.ensure_sync(self.view_functions[rule.endpoint])(**view_args)
  File "/Users/dorritochan/Documents/IT dojo/POTTERY/potterylog/venv/lib/python3.9/site-packages/flask_login/utils.py", line 290, in decorated_view
    return current_app.ensure_sync(func)(*args, **kwargs)
  File "/Users/dorritochan/Documents/IT dojo/POTTERY/potterylog/app/controller.py", line 334, in edit_pot
    populate_select_field_data(form, pot)
  File "/Users/dorritochan/Documents/IT dojo/POTTERY/potterylog/app/utils.py", line 67, in populate_select_field_data
    print(getattr(form, 'made_with_clay.data')) # Returns 2
AttributeError: 'AddPotForm' object has no attribute 'made_with_clay.data'
2023-09-06 21:18:30,884 INFO: Potterylog startup [in /Users/dorritochan/Documents/IT dojo/POTTERY/potterylog/app/__init__.py:41]
